function f() {
  try {
    alert('начало');
    return "result";
  } catch (e) {
    /// ...
  } finally {
    alert('очистка!');
  }
}

f(); // очистка!
//Например, когда есть return внутри try..catch. Секция finally работает в любом случае при любом выходе из try..catch, даже через return: сразу после того как try..catch выполнится, но до того, как вызывающий код получит контроль.